[2023-11-19 17:41:45,250] torch.distributed.run: [WARNING] master_addr is only used for static rdzv_backend and when rdzv_endpoint is not specified.
/home/liu/miniconda3/envs/ChatGLM/bin/python: can't open file '/home/liu/ChatGLM3/finetune.py': [Errno 2] No such file or directory
[2023-11-19 17:41:50,403] torch.distributed.elastic.multiprocessing.api: [ERROR] failed (exitcode: 2) local_rank: 0 (pid: 40796) of binary: /home/liu/miniconda3/envs/ChatGLM/bin/python
Traceback (most recent call last):
  File "/home/liu/miniconda3/envs/ChatGLM/bin/torchrun", line 8, in <module>
    sys.exit(main())
  File "/home/liu/miniconda3/envs/ChatGLM/lib/python3.10/site-packages/torch/distributed/elastic/multiprocessing/errors/__init__.py", line 346, in wrapper
    return f(*args, **kwargs)
  File "/home/liu/miniconda3/envs/ChatGLM/lib/python3.10/site-packages/torch/distributed/run.py", line 806, in main
    run(args)
  File "/home/liu/miniconda3/envs/ChatGLM/lib/python3.10/site-packages/torch/distributed/run.py", line 797, in run
    elastic_launch(
  File "/home/liu/miniconda3/envs/ChatGLM/lib/python3.10/site-packages/torch/distributed/launcher/api.py", line 134, in __call__
    return launch_agent(self._config, self._entrypoint, list(args))
  File "/home/liu/miniconda3/envs/ChatGLM/lib/python3.10/site-packages/torch/distributed/launcher/api.py", line 264, in launch_agent
    raise ChildFailedError(
torch.distributed.elastic.multiprocessing.errors.ChildFailedError: 
============================================================
finetune.py FAILED
------------------------------------------------------------
Failures:
  <NO_OTHER_FAILURES>
------------------------------------------------------------
Root Cause (first observed failure):
[0]:
  time      : 2023-11-19_17:41:50
  host      : SYS-420GR-TR
  rank      : 0 (local_rank: 0)
  exitcode  : 2 (pid: 40796)
  error_file: <N/A>
  traceback : To enable traceback see: https://pytorch.org/docs/stable/elastic/errors.html
============================================================
